Workbook

Sheet Today
A1: A7 — today | B1: =TODAY() -> 46311
A3: Showing | B3: =IF($B$44>131,"The school year has ended.",IF(INDEX('Scope & Sequence'!$A$2:$A$132,$B$44)=TODAY(),"Today's class",IF(INDEX('Scope & Sequence'!$A$2:$A$132,$B$44)<TODAY(),"The PM3 window (3–28 May)","Next class: "&TEXT(INDEX('Scope & Sequence'!$A$2:$A$132,$B$44),"dddd d mmmm")))) -> Today's class
A5: Lesson | B5: =IF($B$44>131,"",INDEX('Scope & Sequence'!$D$2:$D$132,$B$44)&" "&INDEX('Scope & Sequence'!$E$2:$E$132,$B$44)) -> 4.01 Add and subtract in scientific notation
A6: Learning target | B6: =IF($B$44>131,"",INDEX('Scope & Sequence'!$T$2:$T$132,$B$44)&"") -> I can add and subtract two numbers written in scientific notation, and write the answer in scientific notation.
A7: Essential question | B7: =IF($B$44>131,"",INDEX('Scope & Sequence'!$U$2:$U$132,$B$44)&"") -> Why must two numbers written in scientific notation carry the same power of ten before they can be added?
A8: Vocabulary | B8: =IF($B$44>131,"",INDEX('Scope & Sequence'!$V$2:$V$132,$B$44)&"") -> scientific notation, coefficient, common power of ten
A9: Benchmark | B9: =IF($B$44>131,"",INDEX('Scope & Sequence'!$W$2:$W$132,$B$44)&"") -> 8.NSO.1.5
A10: IXL assigned | B10: =IF($B$44>131,"",IF(INDEX('Scope & Sequence'!$R$2:$R$132,$B$44)&""="","none",INDEX('Scope & Sequence'!$R$2:$R$132,$B$44)&" — due "&TEXT(INDEX('Scope & Sequence'!$S$2:$S$132,$B$44),"ddd d mmm"))) -> Add and subtract numbers written in scientific notation — HUR — due Mon 19 Oct
A11: IXL due at the start of class | B11: =IF($B$44>131,"",IFERROR(INDEX('IXL tracker'!$D$5:$D$86,MATCH(INDEX('Scope & Sequence'!$A$2:$A$132,$B$44),'IXL tracker'!$G$5:$G$86,0)),"nothing due")) -> nothing due
A12: Closure question | B12: =IF($B$44>131,"",INDEX('Scope & Sequence'!$Z$2:$Z$132,$B$44)&"") -> Devon writes (1.9 × 10²) + (6.6 × 10⁴) = 8.5 × 10⁶. Name the two mistakes he made, and give the correct sum.
A14: Open
A15: Slides (PDF) | B15: =IF($B$44>131,"—",IF(INDEX(Links!$B$2:$B$132,$B$44)&""="","—",HYPERLINK(INDEX(Links!$B$2:$B$132,$B$44),INDEX('Scope & Sequence'!$F$2:$F$132,$B$44)&""))) -> open
A16: Slides (PowerPoint) | B16: =IF($B$44>131,"—",IF(INDEX(Links!$C$2:$C$132,$B$44)&""="","—",HYPERLINK(INDEX(Links!$C$2:$C$132,$B$44),INDEX('Scope & Sequence'!$G$2:$G$132,$B$44)&""))) -> open
A17: Teacher Edition | B17: =IF($B$44>131,"—",IF(INDEX(Links!$D$2:$D$132,$B$44)&""="","—",HYPERLINK(INDEX(Links!$D$2:$D$132,$B$44),INDEX('Scope & Sequence'!$H$2:$H$132,$B$44)&""))) -> open
A18: Lesson Plan | B18: =IF($B$44>131,"—",IF(INDEX(Links!$E$2:$E$132,$B$44)&""="","—",HYPERLINK(INDEX(Links!$E$2:$E$132,$B$44),INDEX('Scope & Sequence'!$I$2:$I$132,$B$44)&""))) -> open
A19: Question Bank | B19: =IF($B$44>131,"—",IF(INDEX(Links!$F$2:$F$132,$B$44)&""="","—",HYPERLINK(INDEX(Links!$F$2:$F$132,$B$44),INDEX('Scope & Sequence'!$J$2:$J$132,$B$44)&""))) -> open
A20: Bank key | B20: =IF($B$44>131,"—",IF(INDEX(Links!$G$2:$G$132,$B$44)&""="","—",HYPERLINK(INDEX(Links!$G$2:$G$132,$B$44),INDEX('Scope & Sequence'!$K$2:$K$132,$B$44)&""))) -> key
A21: Bank – Additional | B21: =IF($B$44>131,"—",IF(INDEX(Links!$H$2:$H$132,$B$44)&""="","—",HYPERLINK(INDEX(Links!$H$2:$H$132,$B$44),INDEX('Scope & Sequence'!$L$2:$L$132,$B$44)&""))) -> open
A22: Additional key | B22: =IF($B$44>131,"—",IF(INDEX(Links!$I$2:$I$132,$B$44)&""="","—",HYPERLINK(INDEX(Links!$I$2:$I$132,$B$44),INDEX('Scope & Sequence'!$M$2:$M$132,$B$44)&""))) -> key
A23: Independent Set | B23: =IF($B$44>131,"—",IF(INDEX(Links!$J$2:$J$132,$B$44)&""="","—",HYPERLINK(INDEX(Links!$J$2:$J$132,$B$44),INDEX('Scope & Sequence'!$N$2:$N$132,$B$44)&""))) -> open
A24: Independent key | B24: =IF($B$44>131,"—",IF(INDEX(Links!$K$2:$K$132,$B$44)&""="","—",HYPERLINK(INDEX(Links!$K$2:$K$132,$B$44),INDEX('Scope & Sequence'!$O$2:$O$132,$B$44)&""))) -> key
A25: Unit folder | B25: =IF($B$44>131,"—",IF(INDEX(Links!$L$2:$L$132,$B$44)&""="","—",HYPERLINK(INDEX(Links!$L$2:$L$132,$B$44),INDEX('Scope & Sequence'!$P$2:$P$132,$B$44)&""))) -> folder
A26: Everything for this lesson | B26: =IF($B$44>131,"—",IF(INDEX(Links!$M$2:$M$132,$B$44)&""="","—",HYPERLINK(INDEX(Links!$M$2:$M$132,$B$44),INDEX('Scope & Sequence'!$Q$2:$Q$132,$B$44)&""))) -> search
A28: Coming up
A29: Date | B29: Lesson | C29: Slides
A30: =IF(($B$44+1)>131,"",INDEX('Scope & Sequence'!$A$2:$A$132,($B$44+1))) -> 46314 | B30: =IF(($B$44+1)>131,"",INDEX('Scope & Sequence'!$D$2:$D$132,($B$44+1))&" "&INDEX('Scope & Sequence'!$E$2:$E$132,($B$44+1))) -> 4.02+03 Multiply and divide in scientific notation | C30: =IF(($B$44+1)>131,"",IF(INDEX(Links!$B$2:$B$132,($B$44+1))&""="","—",HYPERLINK(INDEX(Links!$B$2:$B$132,($B$44+1)),INDEX('Scope & Sequence'!$F$2:$F$132,($B$44+1))&""))) -> open
A31: =IF(($B$44+2)>131,"",INDEX('Scope & Sequence'!$A$2:$A$132,($B$44+2))) -> 46315 | B31: =IF(($B$44+2)>131,"",INDEX('Scope & Sequence'!$D$2:$D$132,($B$44+2))&" "&INDEX('Scope & Sequence'!$E$2:$E$132,($B$44+2))) -> 4.04 Real-world scientific notation; significant digits | C31: =IF(($B$44+2)>131,"",IF(INDEX(Links!$B$2:$B$132,($B$44+2))&""="","—",HYPERLINK(INDEX(Links!$B$2:$B$132,($B$44+2)),INDEX('Scope & Sequence'!$F$2:$F$132,($B$44+2))&""))) -> open
A32: =IF(($B$44+3)>131,"",INDEX('Scope & Sequence'!$A$2:$A$132,($B$44+3))) -> 46316 | B32: =IF(($B$44+3)>131,"",INDEX('Scope & Sequence'!$D$2:$D$132,($B$44+3))&" "&INDEX('Scope & Sequence'!$E$2:$E$132,($B$44+3))) -> 4.05 Expressions with radicals (perfect squares to 225, cubes −125 to 125) | C32: =IF(($B$44+3)>131,"",IF(INDEX(Links!$B$2:$B$132,($B$44+3))&""="","—",HYPERLINK(INDEX(Links!$B$2:$B$132,($B$44+3)),INDEX('Scope & Sequence'!$F$2:$F$132,($B$44+3))&""))) -> open
A33: =IF(($B$44+4)>131,"",INDEX('Scope & Sequence'!$A$2:$A$132,($B$44+4))) -> 46317 | B33: =IF(($B$44+4)>131,"",INDEX('Scope & Sequence'!$D$2:$D$132,($B$44+4))&" "&INDEX('Scope & Sequence'!$E$2:$E$132,($B$44+4))) -> 4.06 Order of operations with exponents and radicals | C33: =IF(($B$44+4)>131,"",IF(INDEX(Links!$B$2:$B$132,($B$44+4))&""="","—",HYPERLINK(INDEX(Links!$B$2:$B$132,($B$44+4)),INDEX('Scope & Sequence'!$F$2:$F$132,($B$44+4))&""))) -> open
A34: =IF(($B$44+5)>131,"",INDEX('Scope & Sequence'!$A$2:$A$132,($B$44+5))) -> 46318 | B34: =IF(($B$44+5)>131,"",INDEX('Scope & Sequence'!$D$2:$D$132,($B$44+5))&" "&INDEX('Scope & Sequence'!$E$2:$E$132,($B$44+5))) -> 4.07+08 Real-world order-of-operations problems | C34: =IF(($B$44+5)>131,"",IF(INDEX(Links!$B$2:$B$132,($B$44+5))&""="","—",HYPERLINK(INDEX(Links!$B$2:$B$132,($B$44+5)),INDEX('Scope & Sequence'!$F$2:$F$132,($B$44+5))&""))) -> open
A36: This tab follows today's date: on a class day it shows that day; on a weekend or holiday, the next class day. A link opens the document in Google Drive — your own edited copy if you have made one. Where your Drive does not have the file yet, it opens Drive showing the one file with that name.
A44: Plan row shown | B44: =IF(TODAY()>$B$45,131+1,MIN(COUNTIF('Scope & Sequence'!$A$2:$A$132,"<"&TODAY())+1,131)) -> 17
A45: Last day of school | B45: 46535

Sheet Scope & Sequence
A1: Date | B1: Day | C1: Unit | D1: Lesson | E1: What is taught | F1: Slides (PDF) | G1: Slides (PowerPoint) | H1: Teacher Edition | I1: Lesson Plan | J1: Question Bank | K1: Bank key | L1: Bank – Additional | M1: Additional key | N1: Independent Set | O1: Independent key | P1: Unit folder | Q1: Everything for this lesson | R1: IXL skills — all required, code | S1: IXL due | T1: Learning target | U1: Essential question | V1: Vocabulary | W1: Benchmark | X1: Benchmark wording | Y1: MTRs (tap for where they show up) | Z1: Closure question (board 9) | AA1: Closure answer | AB1: Math Nation lesson(s)
A2: 46288 | B2: Wed (43 min) | C2: 3 | D2: 3.01 | E2: Product laws of exponents | F2: =HYPERLINK(Links!$B$2,"open") -> open | G2: =HYPERLINK(Links!$C$2,"open") -> open | H2: =HYPERLINK(Links!$D$2,"open") -> open | I2: =HYPERLINK(Links!$E$2,"open") -> open | J2: =HYPERLINK(Links!$F$2,"open") -> open | K2: =HYPERLINK(Links!$G$2,"key") -> key | L2: =HYPERLINK(Links!$H$2,"open") -> open | M2: =HYPERLINK(Links!$I$2,"key") -> key | N2: =HYPERLINK(Links!$J$2,"open") -> open | O2: =HYPERLINK(Links!$K$2,"key") -> key | P2: =HYPERLINK(Links!$L$2,"folder") -> folder | Q2: =HYPERLINK(Links!$M$2,"search") -> search | R2: Evaluate powers — SZQ; Multiplication with exponents — 5SK; Power rule — 8DA; Understanding exponents — BFA | S2: 46289 | T2: I can use the product of powers, power of a product, power of a power and identity laws to rewrite and evaluate a numerical expression. | U2: How can the laws of exponents be used to write an equivalent expression? | V2: base, exponent, power, product of powers law, power of a product law, power of a power law, identity exponent law | W2: 7.NSO.1.1 · 8.NSO.1.3 | X2: MA.7.NSO.1.1 — Know and apply the Laws of Exponents to evaluate numerical expressions and generate equivalent numerical expressions, limited to whole-number exponents and rational number bases. MA.8.NSO.1.3 — Extend previous understanding of the Laws of Exponents to include integer exponents. Apply the Laws of Exponents to evaluate numerical expressions and generate equivalent numerical expressions, limited to integer exponents and rational number bases, with procedural fluency. | Y2: MA.K12.MTR.5.1 Use patterns and structure to help understand and connect mathematical concepts. MA.K12.MTR.3.1 Complete tasks with mathematical fluency. MA.K12.MTR.4.1 Engage in discussions that reflect on the mathematical thinking of self and others. | Z2: Aiyanna says she can use the power of a product law to evaluate (9 + (−3))³. Is she right? | AA2: No — (9 + (−3))³ = 6³ = 216 | AB2: 3.1 Product Laws of Exponents
A3: 46289 | B3: Thu | C3: 3 | D3: 3.02 | E3: Quotient laws of exponents | F3: =HYPERLINK(Links!$B$3,"open") -> open | G3: =HYPERLINK(Links!$C$3,"open") -> open | H3: =HYPERLINK(Links!$D$3,"open") -> open | I3: =HYPERLINK(Links!$E$3,"open") -> open | J3: =HYPERLINK(Links!$F$3,"open") -> open | K3: =HYPERLINK(Links!$G$3,"key") -> key | L3: =HYPERLINK(Links!$H$3,"open") -> open | M3: =HYPERLINK(Links!$I$3,"key") -> key | N3: =HYPERLINK(Links!$J$3,"open") -> open | O3: =HYPERLINK(Links!$K$3,"key") -> key | P3: =HYPERLINK(Links!$L$3,"folder") -> folder | Q3: =HYPERLINK(Links!$M$3,"search") -> search | R3: Powers with negative bases — WFW; Division with exponents — XNC; Identify equivalent expressions involving whole-number exponents — KBE | S3: 46290 | T3: I can use the quotient of powers, power of a quotient and zero exponent laws to rewrite and evaluate a numerical expression. | U3: Why must the bases be the same to apply the quotient of powers law? | V3: quotient of powers law, power of a quotient law, zero exponent law | W3: 7.NSO.1.1 · 8.NSO.1.3 | X3: MA.7.NSO.1.1 — Know and apply the Laws of Exponents to evaluate numerical expressions and generate equivalent numerical expressions, limited to whole-number exponents and rational number bases. MA.8.NSO.1.3 — Extend previous understanding of the Laws of Exponents to include integer exponents. Apply the Laws of Exponents to evaluate numerical expressions and generate equivalent numerical expressions, limited to integer exponents and rational number bases, with procedural fluency. | Y3: MA.K12.MTR.5.1 Use patterns and structure to help understand and connect mathematical concepts. MA.K12.MTR.6.1 Assess the reasonableness of solutions. MA.K12.MTR.4.1 Engage in discussions that reflect on the mathematical thinking of self and others. | Z3: Hannah cancels 6²/6² to 1. Sebastian subtracts to 6⁰. Who is right? | AA3: Both — 6⁰ = 1 | AB3: 3.2 Quotient Laws of Exponents
A4: 46290 | B4: Fri | C4: 3 | D4: 3.03 | E4: Exponential expressions | F4: =HYPERLINK(Links!$B$4,"open") -> open | G4: =HYPERLINK(Links!$C$4,"open") -> open | H4: =HYPERLINK(Links!$D$4,"open") -> open | I4: =HYPERLINK(Links!$E$4,"open") -> open | J4: =HYPERLINK(Links!$F$4,"open") -> open | K4: =HYPERLINK(Links!$G$4,"key") -> key | L4: =HYPERLINK(Links!$H$4,"open") -> open | M4: =HYPERLINK(Links!$I$4,"key") -> key | N4: =HYPERLINK(Links!$J$4,"open") -> open | O4: =HYPERLINK(Links!$K$4,"key") -> key | P4: =HYPERLINK(Links!$L$4,"folder") -> folder | Q4: =HYPERLINK(Links!$M$4,"search") -> search | R4: Evaluate expressions using properties of exponents — ZE9 | S4: 46293 | T4: I can apply more than one law of exponents to evaluate an expression and to write an equivalent one. | U4: How can the laws of exponents be used to generate equivalent numeric expressions? | V4: equivalent expressions, evaluate, plan | W4: 7.NSO.1.1 · 8.NSO.1.3 | X4: MA.7.NSO.1.1 — Know and apply the Laws of Exponents to evaluate numerical expressions and generate equivalent numerical expressions, limited to whole-number exponents and rational number bases. MA.8.NSO.1.3 — Extend previous understanding of the Laws of Exponents to include integer exponents. Apply the Laws of Exponents to evaluate numerical expressions and generate equivalent numerical expressions, limited to integer exponents and rational number bases, with procedural fluency. | Y4: MA.K12.MTR.2.1 Demonstrate understanding by representing problems in multiple ways. MA.K12.MTR.3.1 Complete tasks with mathematical fluency. MA.K12.MTR.6.1 Assess the reasonableness of solutions. | Z4: Winston writes (4⁷/4⁴)² = (4³)². Yvette writes (4⁷/4⁴)² = 4¹⁴/4⁸. Do they get the same value? Explain. | AA4: Yes — both give 4⁶ = 4,096 | AB4: 3.3 Exponential Expressions
A5: 46293 | B5: Mon | C5: 3 | D5: 3.04 | E5: Negative exponent law | F5: =HYPERLINK(Links!$B$5,"open") -> open | G5: =HYPERLINK(Links!$C$5,"open") -> open | H5: =HYPERLINK(Links!$D$5,"open") -> open | I5: =HYPERLINK(Links!$E$5,"open") -> open | J5: =HYPERLINK(Links!$F$5,"open") -> open | K5: =HYPERLINK(Links!$G$5,"key") -> key | L5: =HYPERLINK(Links!$H$5,"open") -> open | M5: =HYPERLINK(Links!$I$5,"key") -> key | N5: =HYPERLINK(Links!$J$5,"open") -> open | O5: =HYPERLINK(Links!$K$5,"key") -> key | P5: =HYPERLINK(Links!$L$5,"folder") -> folder | Q5: =HYPERLINK(Links!$M$5,"search") -> search | R5: Understanding negative exponents — YBB; Evaluate powers with negative exponents — WGS | S5: 46294 | T5: I can rewrite a power with a negative exponent using a positive exponent, and evaluate it. | U5: How do you evaluate a numerical expression that has a negative exponent? | V5: negative exponent law, reciprocal, opposite | W5: 8.NSO.1.3 | X5: MA.8.NSO.1.3 — Extend previous understanding of the Laws of Exponents to include integer exponents. Apply the Laws of Exponents to evaluate numerical expressions and generate equivalent numerical expressions, limited to integer exponents and rational number bases, with procedural fluency. | Y5: MA.K12.MTR.5.1 Use patterns and structure to help understand and connect mathematical concepts. MA.K12.MTR.4.1 Engage in discussions that reflect on the mathematical thinking of self and others. MA.K12.MTR.6.1 Assess the reasonableness of solutions. | Z5: Ellen says the value of 12⁻² is −144. Explain why she is wrong, and show the correct value. | AA5: 12⁻² = 1/12² = 1/144 | AB5: 3.4 Negative Exponent Law
A6: 46294 | B6: Tue | C6: 3 | D6: 3.05 | E6: Applying exponent laws | F6: =HYPERLINK(Links!$B$6,"open") -> open | G6: =HYPERLINK(Links!$C$6,"open") -> open | H6: =HYPERLINK(Links!$D$6,"open") -> open | I6: =HYPERLINK(Links!$E$6,"open") -> open | J6: =HYPERLINK(Links!$F$6,"open") -> open | K6: =HYPERLINK(Links!$G$6,"key") -> key | L6: =HYPERLINK(Links!$H$6,"open") -> open | M6: =HYPERLINK(Links!$I$6,"key") -> key | N6: =HYPERLINK(Links!$J$6,"open") -> open | O6: =HYPERLINK(Links!$K$6,"key") -> key | P6: =HYPERLINK(Links!$L$6,"folder") -> folder | Q6: =HYPERLINK(Links!$M$6,"search") -> search | R6: Identify equivalent expressions involving exponents I — VLM | S6: 46295 | T6: I can rewrite a rational base with a negative exponent using a positive exponent, and apply several laws to generate an equivalent expression. | U6: How do you rewrite a rational base with a negative exponent as an equivalent expression with a positive exponent? | V6: reciprocal of a fraction, rational base with a negative exponent | W6: 8.NSO.1.3 | X6: MA.8.NSO.1.3 — Extend previous understanding of the Laws of Exponents to include integer exponents. Apply the Laws of Exponents to evaluate numerical expressions and generate equivalent numerical expressions, limited to integer exponents and rational number bases, with procedural fluency. | Y6: MA.K12.MTR.5.1 Use patterns and structure to help understand and connect mathematical concepts. MA.K12.MTR.4.1 Engage in discussions that reflect on the mathematical thinking of self and others. MA.K12.MTR.6.1 Assess the reasonableness of solutions. | Z6: Marco says (−4/11)⁻⁷ can be rewritten as (4/11)⁷ because 'two negatives make a positive.' Is he right? | AA6: No — (−4/11)⁻⁷ = (−11/4)⁷ | AB6: 3.5 Applying Exponent Laws
A7: 46295 | B7: Wed (43 min) | C7: 3 | D7: 3.06+07 | E7: Evaluating and equivalent expressions with integer exponents | F7: =HYPERLINK(Links!$B$7,"open") -> open | G7: =HYPERLINK(Links!$C$7,"open") -> open | H7: =HYPERLINK(Links!$D$7,"open") -> open | I7: =HYPERLINK(Links!$E$7,"open") -> open | J7: =HYPERLINK(Links!$F$7,"open") -> open | K7: =HYPERLINK(Links!$G$7,"key") -> key | L7: =HYPERLINK(Links!$H$7,"open") -> open | M7: =HYPERLINK(Links!$I$7,"key") -> key | N7: =HYPERLINK(Links!$J$7,"open") -> open | O7: =HYPERLINK(Links!$K$7,"key") -> key | P7: =HYPERLINK(Links!$L$7,"folder") -> folder | Q7: =HYPERLINK(Links!$M$7,"search") -> search | R7: Evaluate expressions using properties of exponents — 6T7; Identify equivalent expressions involving exponents II — QDM | S7: 46296 | T7: I can evaluate an expression with integer exponents using the laws, and decide whether two expressions with different bases are equivalent. | U7: How do you determine whether two expressions are equivalent when they do not have the same base? | V7: common base, equivalent | W7: 8.NSO.1.3 | X7: MA.8.NSO.1.3 — Extend previous understanding of the Laws of Exponents to include integer exponents. Apply the Laws of Exponents to evaluate numerical expressions and generate equivalent numerical expressions, limited to integer exponents and rational number bases, with procedural fluency. | Y7: MA.K12.MTR.2.1 Demonstrate understanding by representing problems in multiple ways. MA.K12.MTR.5.1 Use patterns and structure to help understand and connect mathematical concepts. MA.K12.MTR.6.1 Assess the reasonableness of solutions. | Z7: Xavier says (1/9)²·3⁻⁵ and (1/3)⁶·9⁻¹ are equivalent because both can be written as 3⁻⁹. Do you agree? | AA7: No — the second is 3⁻⁸, not 3⁻⁹ | AB7: 3.6 Evaluating Numerical Expressions with Integer Exponents 3.7 Equivalent Expressions
A8: 46296 | B8: Thu | C8: 3 | D8: extra | E8: A day off the plan (the log does not say which day, or why) | P8: =HYPERLINK(Links!$L$8,"folder") -> folder
A9: 46297 | B9: Fri | C9: 3 | D9: extra | E9: Extra review day | P9: =HYPERLINK(Links!$L$9,"folder") -> folder
A10: 46300 | B10: Mon | C10: 3 | D10: T-A1 | E10: Thread A: the same laws with variable bases (14.1–14.2) | F10: =HYPERLINK(Links!$B$10,"open") -> open | G10: =HYPERLINK(Links!$C$10,"open") -> open | H10: =HYPERLINK(Links!$D$10,"open") -> open | I10: =HYPERLINK(Links!$E$10,"open") -> open | J10: =HYPERLINK(Links!$F$10,"open") -> open | K10: =HYPERLINK(Links!$G$10,"key") -> key | L10: =HYPERLINK(Links!$H$10,"open") -> open | M10: =HYPERLINK(Links!$I$10,"key") -> key | N10: =HYPERLINK(Links!$J$10,"open") -> open | O10: =HYPERLINK(Links!$K$10,"key") -> key | P10: =HYPERLINK(Links!$L$10,"folder") -> folder | Q10: =HYPERLINK(Links!$M$10,"search") -> search | R10: Multiply powers: variable bases — TR9; Powers of a power: variable bases — 2CU; Divide monomials with positive exponents — C8L | S10: 46301 | T10: I can multiply and divide monomials, and raise a monomial to a power, by applying the laws of exponents to variable bases. | U10: Do the laws of exponents change when the base is a variable? | V10: monomial, coefficient, like bases | W10: 8.AR.1.1 | X10: MA.8.AR.1.1 — Apply the Laws of Exponents to generate equivalent algebraic expressions, limited to integer exponents and monomial bases. | Y10: MA.K12.MTR.5.1 Use patterns and structure to help understand and connect mathematical concepts. MA.K12.MTR.3.1 Complete tasks with mathematical fluency. MA.K12.MTR.4.1 Engage in discussions that reflect on the mathematical thinking of self and others. | Z10: Rachel writes (14a³b)³ as 14 · 14 · 14 · a · a · a · a · a · a · a · a · a · b · b · b. Justina writes it as 2,744a⁹b³. Who is correct? Explain. | AA10: Both are correct; 14³ = 2,744, nine a's make a⁹, and b · b · b = b³. | AB10: 14.1 Applying Exponent Laws to Algebraic Expressions – Part 1 14.2 … Part 2
A11: 46301 | B11: Tue | C11: 3 | D11: T-A2 | E11: Thread A: negative exponents and multiple laws, variable bases (14.3–14.4) | F11: =HYPERLINK(Links!$B$11,"open") -> open | G11: =HYPERLINK(Links!$C$11,"open") -> open | H11: =HYPERLINK(Links!$D$11,"open") -> open | I11: =HYPERLINK(Links!$E$11,"open") -> open | J11: =HYPERLINK(Links!$F$11,"open") -> open | K11: =HYPERLINK(Links!$G$11,"key") -> key | L11: =HYPERLINK(Links!$H$11,"open") -> open | M11: =HYPERLINK(Links!$I$11,"key") -> key | N11: =HYPERLINK(Links!$J$11,"open") -> open | O11: =HYPERLINK(Links!$K$11,"key") -> key | P11: =HYPERLINK(Links!$L$11,"folder") -> folder | Q11: =HYPERLINK(Links!$M$11,"search") -> search | R11: Variables with negative exponents — 2NL; Multiply and divide powers: variable bases — 85P | S11: 46302 | T11: I can rewrite an algebraic expression with negative exponents using only positive exponents, and apply several laws of exponents to a monomial expression. | U11: What does a negative exponent on a variable mean, and how do several laws combine in one expression? | V11: negative exponent law, simplified form | W11: 8.AR.1.1 | X11: MA.8.AR.1.1 — Apply the Laws of Exponents to generate equivalent algebraic expressions, limited to integer exponents and monomial bases. | Y11: MA.K12.MTR.5.1 Use patterns and structure to help understand and connect mathematical concepts. MA.K12.MTR.6.1 Assess the reasonableness of solutions. MA.K12.MTR.4.1 Engage in discussions that reflect on the mathematical thinking of self and others. | Z11: How are x⁵ and x⁻⁵ related? Explain, and give the value of each when x = 2. | AA11: x⁻⁵ is the reciprocal of x⁵. When x = 2: x⁵ = 32 and x⁻⁵ = 1/32. | AB11: 14.3 Algebraic Expressions with Negative Exponents 14.4 Applying Multiple Laws of Exponents
A12: 46302 | B12: Wed (43 min) | C12: 3 | D12: 3.08 | E12: Large numbers in scientific notation | F12: =HYPERLINK(Links!$B$12,"open") -> open | G12: =HYPERLINK(Links!$C$12,"open") -> open | H12: =HYPERLINK(Links!$D$12,"open") -> open | I12: =HYPERLINK(Links!$E$12,"open") -> open | J12: =HYPERLINK(Links!$F$12,"open") -> open | K12: =HYPERLINK(Links!$G$12,"key") -> key | L12: =HYPERLINK(Links!$H$12,"open") -> open | M12: =HYPERLINK(Links!$I$12,"key") -> key | N12: =HYPERLINK(Links!$J$12,"open") -> open | O12: =HYPERLINK(Links!$K$12,"key") -> key | P12: =HYPERLINK(Links!$L$12,"folder") -> folder | Q12: =HYPERLINK(Links!$M$12,"search") -> search | R12: Convert between standard and scientific notation: large numbers — 2AL; Compare large numbers — WEZ; Powers of ten — LJQ | S12: 46304 | T12: I can write a large number in scientific notation, read one back into standard form, and find how many times larger one number is than another. | U12: How does a power of 10 let us write a very large number briefly, and compare two of them? | V12: scientific notation, standard form, coefficient | W12: 8.NSO.1.4 | X12: MA.8.NSO.1.4 — Express numbers in scientific notation to represent and approximate very large or very small quantities. Determine how many times larger or smaller one number is compared to a second number. | Y12: MA.K12.MTR.7.1 Apply mathematics to real-world contexts. MA.K12.MTR.5.1 Use patterns and structure to help understand and connect mathematical concepts. MA.K12.MTR.6.1 Assess the reasonableness of solutions. | Z12: Marcus writes 70,000,000 as 70 × 10⁶. Is his expression equal to 70,000,000? Is it scientific notation? Explain. | AA12: Equal, yes. Scientific notation, no: 70 is not less than 10. 7 × 10⁷. | AB12: 3.8 Writing Large Numbers in Scientific Notation
A13: 46303 | B13: Thu | C13: 3 | D13: off | E13: State test — no class | P13: =HYPERLINK(Links!$L$13,"folder") -> folder
A14: 46304 | B14: Fri | C14: 3 | D14: 3.09 | E14: Small numbers in scientific notation; how many times larger | F14: =HYPERLINK(Links!$B$14,"open") -> open | G14: =HYPERLINK(Links!$C$14,"open") -> open | H14: =HYPERLINK(Links!$D$14,"open") -> open | I14: =HYPERLINK(Links!$E$14,"open") -> open | J14: =HYPERLINK(Links!$F$14,"open") -> open | K14: =HYPERLINK(Links!$G$14,"key") -> key | L14: =HYPERLINK(Links!$H$14,"open") -> open | M14: =HYPERLINK(Links!$I$14,"key") -> key | N14: =HYPERLINK(Links!$J$14,"open") -> open | O14: =HYPERLINK(Links!$K$14,"key") -> key | P14: =HYPERLINK(Links!$L$14,"folder") -> folder | Q14: =HYPERLINK(Links!$M$14,"search") -> search | R14: Convert between standard and scientific notation: small numbers — 85M; Compare small numbers — KDR; Powers of ten with negative exponents — SKD | S14: 46308 | T14: I can write very small numbers in scientific notation, read them back, and find how many times larger or smaller one number is than another. | U14: How does a negative power of 10 let us write a very small number, and compare it to another? | V14: negative power of 10, scientific notation | W14: 8.NSO.1.4 | X14: MA.8.NSO.1.4 — Express numbers in scientific notation to represent and approximate very large or very small quantities. Determine how many times larger or smaller one number is compared to a second number. | Y14: MA.K12.MTR.5.1 Use patterns and structure to help understand and connect mathematical concepts. MA.K12.MTR.6.1 Assess the reasonableness of solutions. MA.K12.MTR.7.1 Apply mathematics to real-world contexts. | Z14: Fishing line A is 2 × 10⁻² inch thick. Fishing line B is 6 × 10⁻² inch thick. Which is thicker, and how many times thicker? Give a possible thickness between the two. | AA14: B; 3 times; e.g. 4 × 10⁻² in. | AB14: 3.9 Writing Small Numbers in Scientific Notation
A15: 46308 | B15: Tue | C15: 3 | D15: spiral | E15: Spiral day — mixed retrieval from the unit just finished and the two before it | F15: =HYPERLINK(Links!$B$15,"Unit Review") -> Unit Review | K15: =HYPERLINK(Links!$G$15,"Review key") -> Review key | P15: =HYPERLINK(Links!$L$15,"folder") -> folder
A16: 46309 | B16: Wed (43 min) | C16: 3 | D16: spiral | E16: Spiral day — mixed retrieval from the unit just finished and the two before it | F16: =HYPERLINK(Links!$B$16,"Unit Review") -> Unit Review | K16: =HYPERLINK(Links!$G$16,"Review key") -> Review key | P16: =HYPERLINK(Links!$L$16,"folder") -> folder
A17: 46310 | B17: Thu | C17: 3 | D17: 3.X1 | E17: Unit 3 exam, day 1 | F17: =HYPERLINK(Links!$B$17,"Unit Assessment") -> Unit Assessment | K17: =HYPERLINK(Links!$G$17,"Assessment key") -> Assessment key | P17: =HYPERLINK(Links!$L$17,"folder") -> folder
A18: 46311 | B18: Fri | C18: 4 | D18: 4.01 | E18: Add and subtract in scientific notation | F18: =HYPERLINK(Links!$B$18,"open") -> open | G18: =HYPERLINK(Links!$C$18,"open") -> open | H18: =HYPERLINK(Links!$D$18,"open") -> open | I18: =HYPERLINK(Links!$E$18,"open") -> open | J18: =HYPERLINK(Links!$F$18,"open") -> open | K18: =HYPERLINK(Links!$G$18,"key") -> key | L18: =HYPERLINK(Links!$H$18,"open") -> open | M18: =HYPERLINK(Links!$I$18,"key") -> key | N18: =HYPERLINK(Links!$J$18,"open") -> open | O18: =HYPERLINK(Links!$K$18,"key") -> key | P18: =HYPERLINK(Links!$L$18,"folder") -> folder | Q18: =HYPERLINK(Links!$M$18,"search") -> search | R18: Add and subtract numbers written in scientific notation — HUR | S18: 46314 | T18: I can add and subtract two numbers written in scientific notation, and write the answer in scientific notation. | U18: Why must two numbers written in scientific notation carry the same power of ten before they can be added? | V18: scientific notation, coefficient, common power of ten | W18: 8.NSO.1.5 | X18: MA.8.NSO.1.5 — Add, subtract, multiply and divide numbers expressed in scientific notation with procedural fluency. | Y18: MA.K12.MTR.5.1 Use patterns and structure to help understand and connect mathematical concepts. MA.K12.MTR.6.1 Assess the reasonableness of solutions. MA.K12.MTR.4.1 Engage in discussions that reflect on the mathematical thinking of self and others. | Z18: Devon writes (1.9 × 10²) + (6.6 × 10⁴) = 8.5 × 10⁶. Name the two mistakes he made, and give the correct sum. | AA18: 6.619 × 10⁴ | AB18: 4.1 Adding and Subtracting Numbers Expressed in Scientific Notation
A19: 46314 | B19: Mon | C19: 4 | D19: 4.02+03 | E19: Multiply and divide in scientific notation | F19: =HYPERLINK(Links!$B$19,"open") -> open | G19: =HYPERLINK(Links!$C$19,"open") -> open | H19: =HYPERLINK(Links!$D$19,"open") -> open | I19: =HYPERLINK(Links!$E$19,"open") -> open | J19: =HYPERLINK(Links!$F$19,"open") -> open | K19: =HYPERLINK(Links!$G$19,"key") -> key | L19: =HYPERLINK(Links!$H$19,"open") -> open | M19: =HYPERLINK(Links!$I$19,"key") -> key | N19: =HYPERLINK(Links!$J$19,"open") -> open | O19: =HYPERLINK(Links!$K$19,"key") -> key | P19: =HYPERLINK(Links!$L$19,"folder") -> folder | Q19: =HYPERLINK(Links!$M$19,"search") -> search | R19: Multiply numbers written in scientific notation — YZU; Divide numbers written in scientific notation — SGT | S19: 46315 | T19: I can multiply and divide two numbers written in scientific notation, and write the answer in scientific notation. | U19: Why must the powers of ten match to add, but not to multiply? | V19: product of powers law, quotient of powers law, regrouping a product | W19: 8.NSO.1.5 | X19: MA.8.NSO.1.5 — Add, subtract, multiply and divide numbers expressed in scientific notation with procedural fluency. | Y19: MA.K12.MTR.5.1 Use patterns and structure to help understand and connect mathematical concepts. MA.K12.MTR.3.1 Complete tasks with mathematical fluency. MA.K12.MTR.4.1 Engage in discussions that reflect on the mathematical thinking of self and others. | Z19: For (7.2 × 10¹¹) ÷ (2.4 × 10³), Marcus writes 4.8 × 10⁸ and Sara writes 3 × 10¹⁴. Name what each one did wrong, and give the correct quotient. | AA19: 3 × 10⁸ | AB19: 4.2 Multiplying Numbers Expressed in Scientific Notation 4.3 Dividing Numbers Expressed in Scientific Notation
A20: 46315 | B20: Tue | C20: 4 | D20: 4.04 | E20: Real-world scientific notation; significant digits | F20: =HYPERLINK(Links!$B$20,"open") -> open | G20: =HYPERLINK(Links!$C$20,"open") -> open | H20: =HYPERLINK(Links!$D$20,"open") -> open | I20: =HYPERLINK(Links!$E$20,"open") -> open | J20: =HYPERLINK(Links!$F$20,"open") -> open | K20: =HYPERLINK(Links!$G$20,"key") -> key | L20: =HYPERLINK(Links!$H$20,"open") -> open | M20: =HYPERLINK(Links!$I$20,"key") -> key | N20: =HYPERLINK(Links!$J$20,"open") -> open | O20: =HYPERLINK(Links!$K$20,"key") -> key | P20: =HYPERLINK(Links!$L$20,"folder") -> folder | Q20: =HYPERLINK(Links!$M$20,"search") -> search | R20: Add, subtract, multiply, and divide numbers written in scientific notation: word problems — D5S | S20: 46316 | T20: I can solve a real-world problem with numbers in scientific notation and report the answer with the right number of significant digits. | U20: How much of an answer is worth writing down, when the numbers that produced it were measured? | V20: significant digits, leading zero, measurement | W20: 8.NSO.1.6 | X20: MA.8.NSO.1.6 — Solve real-world problems involving operations with numbers expressed in scientific notation. | Y20: MA.K12.MTR.6.1 Assess the reasonableness of solutions. MA.K12.MTR.7.1 Apply mathematics to real-world contexts. MA.K12.MTR.4.1 Engage in discussions that reflect on the mathematical thinking of self and others. | Z20: Ellis says that because 9,145 has 4 significant digits and 4.8 has 2, the sum 9,145 + 4.8 must be written with 2 significant digits, as 9.1 × 10³. Explain why he is wrong, and give the correct sum. | AA20: 9,150 = 9.150 × 10³ | AB20: 4.4 Solving Real-World Problems Involving Numbers Expressed in Scientific Notation
A21: 46316 | B21: Wed (43 min) | C21: 4 | D21: 4.05 | E21: Expressions with radicals (perfect squares to 225, cubes −125 to 125) | F21: =HYPERLINK(Links!$B$21,"open") -> open | G21: =HYPERLINK(Links!$C$21,"open") -> open | H21: =HYPERLINK(Links!$D$21,"open") -> open | I21: =HYPERLINK(Links!$E$21,"open") -> open | J21: =HYPERLINK(Links!$F$21,"open") -> open | K21: =HYPERLINK(Links!$G$21,"key") -> key | L21: =HYPERLINK(Links!$H$21,"open") -> open | M21: =HYPERLINK(Links!$I$21,"key") -> key | N21: =HYPERLINK(Links!$J$21,"open") -> open | O21: =HYPERLINK(Links!$K$21,"key") -> key | P21: =HYPERLINK(Links!$L$21,"folder") -> folder | Q21: =HYPERLINK(Links!$M$21,"search") -> search | R21: Evaluate radical expressions — D8J | S21: 46318 | T21: I can evaluate an expression that contains square roots, cube roots and integer exponents. | U21: What does the radical bar do to the order in which an expression is evaluated? | V21: radical, radicand, principal square root | W21: 8.NSO.1.7 | X21: MA.8.NSO.1.7 — Solve multi-step mathematical and real-world problems involving the order of operations with rational numbers including exponents and radicals. | Y21: MA.K12.MTR.5.1 Use patterns and structure to help understand and connect mathematical concepts. MA.K12.MTR.6.1 Assess the reasonableness of solutions. MA.K12.MTR.4.1 Engage in discussions that reflect on the mathematical thinking of self and others. | Z21: Simon says that the cube root of −27 is not a real number, because you cannot take the root of a negative. Explain why he is wrong, and give the value. | AA21: −3 | AB21: 4.5 Evaluating Expressions with Radicals
A22: 46317 | B22: Thu | C22: 4 | D22: 4.06 | E22: Order of operations with exponents and radicals | F22: =HYPERLINK(Links!$B$22,"open") -> open | G22: =HYPERLINK(Links!$C$22,"open") -> open | H22: =HYPERLINK(Links!$D$22,"open") -> open | I22: =HYPERLINK(Links!$E$22,"open") -> open | J22: =HYPERLINK(Links!$F$22,"open") -> open | K22: =HYPERLINK(Links!$G$22,"key") -> key | L22: =HYPERLINK(Links!$H$22,"open") -> open | M22: =HYPERLINK(Links!$I$22,"key") -> key | N22: =HYPERLINK(Links!$J$22,"open") -> open | O22: =HYPERLINK(Links!$K$22,"key") -> key | P22: =HYPERLINK(Links!$L$22,"folder") -> folder | Q22: =HYPERLINK(Links!$M$22,"search") -> search | R22: Evaluate radical expressions — D8J | S22: 46318 | T22: I can evaluate a multi-step expression with rational numbers, exponents and radicals by reading its structure. | U22: What decides the order in which an expression is evaluated? | V22: grouping symbol, nested, multi-step expression | W22: 8.NSO.1.7 | X22: MA.8.NSO.1.7 — Solve multi-step mathematical and real-world problems involving the order of operations with rational numbers including exponents and radicals. | Y22: MA.K12.MTR.5.1 Use patterns and structure to help understand and connect mathematical concepts. MA.K12.MTR.3.1 Complete tasks with mathematical fluency. MA.K12.MTR.4.1 Engage in discussions that reflect on the mathematical thinking of self and others. | Z22: Roscoe says that (√n − 11)² is always positive, because a square is always positive. Is he right? Give a value of n that settles it. | AA22: No — at n = 121 the value is 0 | AB22: 4.6 Evaluating Expressions Using the Order of Operations
A23: 46318 | B23: Fri | C23: 4 | D23: 4.07+08 | E23: Real-world order-of-operations problems | F23: =HYPERLINK(Links!$B$23,"open") -> open | G23: =HYPERLINK(Links!$C$23,"open") -> open | H23: =HYPERLINK(Links!$D$23,"open") -> open | I23: =HYPERLINK(Links!$E$23,"open") -> open | J23: =HYPERLINK(Links!$F$23,"open") -> open | K23: =HYPERLINK(Links!$G$23,"key") -> key | L23: =HYPERLINK(Links!$H$23,"open") -> open | M23: =HYPERLINK(Links!$I$23,"key") -> key | N23: =HYPERLINK(Links!$J$23,"open") -> open | O23: =HYPERLINK(Links!$K$23,"key") -> key | P23: =HYPERLINK(Links!$L$23,"folder") -> folder | Q23: =HYPERLINK(Links!$M$23,"search") -> search | R23: Evaluate variable expressions: word problems — DPG | S23: 46321 | T23: I can substitute values into a formula and evaluate it, reading what the situation does rather than hunting for key words. | U23: If key words cannot tell you which operation a problem needs, what can? | V23: formula, substitute, unit | W23: 8.NSO.1.7 | X23: MA.8.NSO.1.7 — Solve multi-step mathematical and real-world problems involving the order of operations with rational numbers including exponents and radicals. | Y23: MA.K12.MTR.7.1 Apply mathematics to real-world contexts. MA.K12.MTR.2.1 Demonstrate understanding by representing problems in multiple ways. MA.K12.MTR.4.1 Engage in discussions that reflect on the mathematical thinking of self and others. | Z23: One pizza order costs 13 dollars plus 2 dollars for each of 5 toppings. Another costs 13 dollars for each of 2 pizzas, plus 5 dollars for delivery. Find both totals, and say why the key words could not have told you. | AA23: 23 dollars and 31 dollars | AB23: 4.7 / 4.8 Evaluating Real-World Problems Using the Order of Operations – Parts 1, 2
A24: 46321 | B24: Mon | C24: 4 | D24: 4.X1 | E24: Unit 4 exam, day 1 | F24: =HYPERLINK(Links!$B$24,"Unit Assessment") -> Unit Assessment | K24: =HYPERLINK(Links!$G$24,"Assessment key") -> Assessment key | P24: =HYPERLINK(Links!$L$24,"folder") -> folder
A25: 46322 | B25: Tue | C25: 4 | D25: 4.X2 | E25: Unit 4 exam, day 2 | F25: =HYPERLINK(Links!$B$25,"Unit Assessment") -> Unit Assessment | K25: =HYPERLINK(Links!$G$25,"Assessment key") -> Assessment key | P25: =HYPERLINK(Links!$L$25,"folder") -> folder
A26: 46323 | B26: Wed (43 min) | C26: 5 | D26: 5.01 | E26: Scale drawings | F26: not built yet | Q26: =HYPERLINK(Links!$M$26,"search") -> search | R26: Scale drawings: find the scale factor, missing side, or missing angle — WEA | S26: 46324 | W26: 7.GR.1.5 | X26: MA.7.GR.1.5 — Solve mathematical and real-world problems involving dimensions and areas of geometric figures, including scale drawings and scale factors. | AB26: 5.1 Scale Drawings
A27: 46324 | B27: Thu | C27: 5 | D27: 5.02+03 | E27: Scale factor: perimeter and area (k and k²) | F27: not built yet | Q27: =HYPERLINK(Links!$M$27,"search") -> search | R27: Perimeter and area: changes in scale — ZC6; Scale drawings: find the scale factor or missing side — XHM | S27: 46325 | W27: 7.GR.1.5 | X27: MA.7.GR.1.5 — Solve mathematical and real-world problems involving dimensions and areas of geometric figures, including scale drawings and scale factors. | AB27: 5.2 Scale Factors – Perimeter & Area 5.3 Solving Problems Involving Perimeter and Area of Geometric Figures
A28: 46325 | B28: Fri | C28: 5 | D28: 5.04 | E28: Real-world scale drawings | F28: not built yet | Q28: =HYPERLINK(Links!$M$28,"search") -> search | R28: Scale drawings: word problems — 84H; Scale drawings: scale factor word problems — KCM | S28: 46328 | W28: 7.GR.1.5 | X28: MA.7.GR.1.5 — Solve mathematical and real-world problems involving dimensions and areas of geometric figures, including scale drawings and scale factors. | AB28: 5.4 Solving Problems Involving Real-World Scale Drawings
A29: 46328 | B29: Mon | C29: 5 | D29: 5.06+07 | E29: Converting length across systems; currency | F29: not built yet | Q29: =HYPERLINK(Links!$M$29,"search") -> search | R29: Convert between customary and metric systems — E8Z; Compare and convert customary units — 4B8; Compare and convert metric units — HW2 | S29: 46330 | W29: 7.AR.3.3 | X29: MA.7.AR.3.3 — Solve mathematical and real-world problems involving the conversion of units across different measurement systems. | AB29: 5.6 Currency Conversions 5.7 Converting Units of Length
A30: 46329 | B30: Tue | C30: 5 | D30: 5.08+09 | E30: Converting mass, area and volume across systems | F30: not built yet | Q30: =HYPERLINK(Links!$M$30,"search") -> search | R30: Convert between customary and metric systems — E8Z; Compare and convert customary units — 4B8; Compare and convert metric units — HW2 | S30: 46330 | W30: 7.AR.3.3 | X30: MA.7.AR.3.3 — Solve mathematical and real-world problems involving the conversion of units across different measurement systems. | AB30: 5.8 Converting Mass and Area 5.9 Converting Units of Volume
A31: 46330 | B31: Wed (43 min) | C31: 5 | D31: 5.10+11 | E31: Multi-step proportion problems | F31: not built yet | Q31: =HYPERLINK(Links!$M$31,"search") -> search | R31: Compare rates: word problems — VVS; Multi-step problems with customary or metric unit conversions — UCT | S31: 46331 | W31: 7.AR.3.3 · 7.AR.4.5 | X31: MA.7.AR.3.3 — Solve mathematical and real-world problems involving the conversion of units across different measurement systems. MA.7.AR.4.5 — Solve real-world problems involving proportional relationships. | AB31: 5.10 Exploring Multi-Step Proportion Problems 5.11 Solving Multi-Step Proportion Problems
A32: 46331 | B32: Thu | C32: 5 | D32: 5.X1 | E32: Unit 5 exam, day 1 | F32: not built yet
A33: 46332 | B33: Fri | C33: 5 | D33: 5.X2 | E33: Unit 5 exam, day 2 | F33: not built yet
A34: 46335 | B34: Mon | C34: 6 | D34: 6.01+02 | E34: Triangle Inequality Theorem; converse of the Pythagorean Theorem | F34: not built yet | Q34: =HYPERLINK(Links!$M$34,"search") -> search | R34: Triangle inequality — 2N5; Converse of the Pythagorean theorem: is it a right triangle? — EQZ | S34: 46336 | W34: 8.GR.1.3 | X34: MA.8.GR.1.3 — Use the Triangle Inequality Theorem to determine if a triangle can be formed from a given set of sides. Use the converse of the Pythagorean Theorem to determine if a right triangle can be formed from a given set of sides. | AB34: 6.1 The Triangle Inequality Theorem and the Converse of the Pythagorean Theorem 6.2 Applying the Triangle Inequality Theorem
A35: 46336 | B35: Tue | C35: 6 | D35: 6.03 | E35: Pythagorean Theorem (memorize) | F35: not built yet | Q35: =HYPERLINK(Links!$M$35,"search") -> search | R35: Pythagorean theorem: find the missing leg or hypotenuse length — MTM | S35: 46338 | W35: 8.GR.1.1 | X35: MA.8.GR.1.1 — Apply the Pythagorean Theorem to solve mathematical and real-world problems involving unknown side lengths in right triangles. | AB35: 6.3 Pythagorean Theorem
A36: 46338 | B36: Thu | C36: 6 | D36: 6.04 | E36: Pythagorean Theorem in real-world problems | F36: not built yet | Q36: =HYPERLINK(Links!$M$36,"search") -> search | R36: Pythagorean theorem: word problems — 87U | S36: 46339 | W36: 8.GR.1.1 | X36: MA.8.GR.1.1 — Apply the Pythagorean Theorem to solve mathematical and real-world problems involving unknown side lengths in right triangles. | AB36: 6.4 Using the Pythagorean Theorem to Solve Real-World Problems
A37: 46339 | B37: Fri | C37: 6 | D37: 6.05 | E37: Distance on the coordinate plane | F37: not built yet | Q37: =HYPERLINK(Links!$M$37,"search") -> search | R37: Find the distance between two points on a horizontal or vertical line — L9V; Find the distance between two points — ZBP | S37: 46342 | W37: 8.GR.1.2 | X37: MA.8.GR.1.2 — Apply the Pythagorean Theorem to solve mathematical and real-world problems involving the distance between two points in a coordinate plane. | AB37: 6.5 Finding Distances on the Coordinate Plane
A38: 46342 | B38: Mon | C38: 6 | D38: 6.06 | E38: Real-world coordinate-plane problems; perimeter | F38: not built yet | Q38: =HYPERLINK(Links!$M$38,"search") -> search | R38: Pythagorean theorem: find the perimeter — VGE | S38: 46343 | W38: 8.GR.1.2 | X38: MA.8.GR.1.2 — Apply the Pythagorean Theorem to solve mathematical and real-world problems involving the distance between two points in a coordinate plane. | AB38: 6.6 Solving Real-World Problems on a Coordinate Plane with the Pythagorean Theorem
A39: 46343 | B39: Tue | C39: 6 | D39: T-B1 | E39: Thread B: angle pairs — supplementary, complementary, vertical, adjacent (16.1) | F39: not built yet | Q39: =HYPERLINK(Links!$M$39,"search") -> search | R39: Identify complementary, supplementary, vertical, adjacent, and congruent angles — HGV; Find measures of complementary, supplementary, vertical, and adjacent angles — R2B; Write and solve equations using angle relationships — DBV | S39: 46344 | W39: 8.GR.1.4 | X39: MA.8.GR.1.4 — Solve mathematical problems involving the relationships between supplementary, complementary, vertical or adjacent angles. | AB39: 16.1 Angle Relationships
A40: 46344 | B40: Wed (43 min) | C40: 6 | D40: T-B2 | E40: Thread B: interior and exterior angles of a triangle (16.2) | F40: not built yet | Q40: =HYPERLINK(Links!$M$40,"search") -> search | R40: Find missing angles in triangles — JFJ; Exterior Angle Theorem — FMP; Triangle Angle-Sum Theorem — 6Q6 | S40: 46345 | W40: 8.GR.1.5 | X40: MA.8.GR.1.5 — Solve problems involving the relationships of interior and exterior angles of a triangle. | AB40: 16.2 Angle Relationships in Triangles
...

Sheet IXL tracker
A1: IXL assignments, 2026–27
A2: Every skill listed is required, to a SmartScore of 67. Fill in the two yellow columns: type ✓ in 'Set up in IXL' once the assignment exists in IXL, and ✓ in 'Scores checked' after you have looked at the scores (for example, row 1 done: ✓ and ✓, Status reads 'done'). Status works itself out from today's date.
A4: # | B4: Assigned | C4: Lesson(s) | D4: Skills — all required | E4: Codes to type into IXL | F4: SmartScore | G4: Due | H4: Set up in IXL | I4: Scores checked | J4: Status | K4: Notes
A5: 1 | B5: 46288 | C5: 3.01 Product laws of exponents | D5: Evaluate powers (SZQ); Multiplication with exponents (5SK); Power rule (8DA); Understanding exponents (BFA) | E5: SZQ, 5SK, 8DA, BFA | F5: 67 | G5: 46289 | J5: =IF(I5="✓","done",IF(TODAY()<B5,"upcoming",IF(TODAY()<G5,"open","due — check scores"))) -> due — check scores
A6: 2 | B6: 46289 | C6: 3.02 Quotient laws of exponents | D6: Powers with negative bases (WFW); Division with exponents (XNC); Identify equivalent expressions involving whole-number exponents (KBE) | E6: WFW, XNC, KBE | F6: 67 | G6: 46290 | J6: =IF(I6="✓","done",IF(TODAY()<B6,"upcoming",IF(TODAY()<G6,"open","due — check scores"))) -> due — check scores
A7: 3 | B7: 46290 | C7: 3.03 Exponential expressions | D7: Evaluate expressions using properties of exponents (ZE9) | E7: ZE9 | F7: 67 | G7: 46293 | J7: =IF(I7="✓","done",IF(TODAY()<B7,"upcoming",IF(TODAY()<G7,"open","due — check scores"))) -> due — check scores
A8: 4 | B8: 46293 | C8: 3.04 Negative exponent law | D8: Understanding negative exponents (YBB); Evaluate powers with negative exponents (WGS) | E8: YBB, WGS | F8: 67 | G8: 46294 | J8: =IF(I8="✓","done",IF(TODAY()<B8,"upcoming",IF(TODAY()<G8,"open","due — check scores"))) -> due — check scores
A9: 5 | B9: 46294 | C9: 3.05 Applying exponent laws | D9: Identify equivalent expressions involving exponents I (VLM) | E9: VLM | F9: 67 | G9: 46295 | J9: =IF(I9="✓","done",IF(TODAY()<B9,"upcoming",IF(TODAY()<G9,"open","due — check scores"))) -> due — check scores
A10: 6 | B10: 46295 | C10: 3.06+07 Evaluating and equivalent expressions with integer exponents | D10: Evaluate expressions using properties of exponents (6T7); Identify equivalent expressions involving exponents II (QDM) | E10: 6T7, QDM | F10: 67 | G10: 46296 | J10: =IF(I10="✓","done",IF(TODAY()<B10,"upcoming",IF(TODAY()<G10,"open","due — check scores"))) -> due — check scores
A11: 7 | B11: 46300 | C11: T-A1 Thread A: the same laws with variable bases (14.1–14.2) | D11: Multiply powers: variable bases (TR9); Powers of a power: variable bases (2CU); Divide monomials with positive exponents (C8L) | E11: TR9, 2CU, C8L | F11: 67 | G11: 46301 | J11: =IF(I11="✓","done",IF(TODAY()<B11,"upcoming",IF(TODAY()<G11,"open","due — check scores"))) -> due — check scores
A12: 8 | B12: 46301 | C12: T-A2 Thread A: negative exponents and multiple laws, variable bases (14.3–14.4) | D12: Variables with negative exponents (2NL); Multiply and divide powers: variable bases (85P) | E12: 2NL, 85P | F12: 67 | G12: 46302 | J12: =IF(I12="✓","done",IF(TODAY()<B12,"upcoming",IF(TODAY()<G12,"open","due — check scores"))) -> due — check scores
A13: 9 | B13: 46302 | C13: 3.08 Large numbers in scientific notation | D13: Convert between standard and scientific notation: large numbers (2AL); Compare large numbers (WEZ); Powers of ten (LJQ) | E13: 2AL, WEZ, LJQ | F13: 67 | G13: 46304 | J13: =IF(I13="✓","done",IF(TODAY()<B13,"upcoming",IF(TODAY()<G13,"open","due — check scores"))) -> due — check scores
A14: 10 | B14: 46304 | C14: 3.09 Small numbers in scientific notation; how many times larger | D14: Convert between standard and scientific notation: small numbers (85M); Compare small numbers (KDR); Powers of ten with negative exponents (SKD) | E14: 85M, KDR, SKD | F14: 67 | G14: 46308 | J14: =IF(I14="✓","done",IF(TODAY()<B14,"upcoming",IF(TODAY()<G14,"open","due — check scores"))) -> due — check scores
A15: 11 | B15: 46311 | C15: 4.01 Add and subtract in scientific notation | D15: Add and subtract numbers written in scientific notation (HUR) | E15: HUR | F15: 67 | G15: 46314 | J15: =IF(I15="✓","done",IF(TODAY()<B15,"upcoming",IF(TODAY()<G15,"open","due — check scores"))) -> open
A16: 12 | B16: 46314 | C16: 4.02+03 Multiply and divide in scientific notation | D16: Multiply numbers written in scientific notation (YZU); Divide numbers written in scientific notation (SGT) | E16: YZU, SGT | F16: 67 | G16: 46315 | J16: =IF(I16="✓","done",IF(TODAY()<B16,"upcoming",IF(TODAY()<G16,"open","due — check scores"))) -> upcoming
... A86: 82 | B86: 46504 | C86: 17.04–06 Predictions from theoretical probability | D86: Make predictions (38C); Write a discrete probability distribution (ELU) | E86: 38C, ELU | F86: 67 | G86: 46505 | J86: =IF(I86="✓","done",IF(TODAY()<B86,"upcoming",IF(TODAY()<G86,"open","due — check scores"))) -> upcoming

Sheet Standards
A1: Benchmark | B1: Grade | C1: Wording | D1: Clarifications and limits | E1: Unit(s) | F1: Taught on | G1: First day | H1: Last day | I1: Reviewed on | J1: Unit test points | K1: IXL skill codes
A2: MA.7.AR.2.2 | B2: 7 | C2: Write and solve two-step equations in one variable within a mathematical or real-world context, where all terms are rational numbers. | D2: Boundary — forms only: px ± q = r and p(x ± q) = r. Variable on either side. → prerequisite for MA.8.AR.2.1 (multi-step, variables both sides). | E2: 1 | F2: Unit 1 (before 23 Sep) | J2: =IF(SUMIF('Unit tests'!$E:$E,A2,'Unit tests'!$C:$C)=0,"",SUMIF('Unit tests'!$E:$E,A2,'Unit tests'!$C:$C))
A3: MA.7.NSO.1.2 | B3: 7 | C3: Rewrite rational numbers in different but equivalent forms including fractions, mixed numbers, repeating decimals and percentages to solve mathematical and real-world problems. | D3: State example: Is 17/3 = 5.6666666667 accurate? This is the benchmark the TI-30XA rounding rule attaches to (Part 8). | E3: 1 | F3: Unit 1 (before 23 Sep) | J3: =IF(SUMIF('Unit tests'!$E:$E,A3,'Unit tests'!$C:$C)=0,"",SUMIF('Unit tests'!$E:$E,A3,'Unit tests'!$C:$C))
A4: MA.8.AR.2.2 | B4: 8 | C4: Solve two-step linear inequalities in one variable and represent solutions algebraically and graphically. | D4: Boundary — forms only: px ± q > r and p(x ± q) > r, p/q/r specific rational numbers, any inequality symbol. Variable may be on either side. | E4: 1 | F4: Unit 1 (before 23 Sep) | I4: PM2-R2 (15 Dec) | J4: =IF(SUMIF('Unit tests'!$E:$E,A4,'Unit tests'!$C:$C)=0,"",SUMIF('Unit tests'!$E:$E,A4,'Unit tests'!$C:$C))
A5: MA.8.AR.2.3 | B5: 8 | C5: Given an equation in the form of x² = p and x³ = q, where p is a whole number and q is an integer, determine the real solutions. | D5: Clarification: focus on understanding that solving x² = p gives both a positive and a negative solution. Boundary: square roots of perfect squares up to 225; cube roots of perfect cubes from −125 to 125. Boundary (B1G-M): students are not required to isolate the x² or x³ term. | E5: 2 | F5: Unit 2 (before 23 Sep) | I5: PM2-R2 (15 Dec) | J5: =IF(SUMIF('Unit tests'!$E:$E,A5,'Unit tests'!$C:$C)=0,"",SUMIF('Unit tests'!$E:$E,A5,'Unit tests'!$C:$C))
A6: MA.8.NSO.1.1 | B6: 8 | C6: Extend previous understanding of rational numbers to define irrational numbers within the real number system. Locate an approximate value of a numerical expression involving irrational numbers on a number line. | D6: Clarification 1: instruction includes the use of number line and rational number approximations, and recognizing pi (π) as an irrational number. Boundary: approximate numerical expressions involving one arithmetic operation, estimating square roots or π. | E6: 2 | F6: Unit 2 (before 23 Sep) | I6: PM2-R1 (14 Dec) | J6: =IF(SUMIF('Unit tests'!$E:$E,A6,'Unit tests'!$C:$C)=0,"",SUMIF('Unit tests'!$E:$E,A6,'Unit tests'!$C:$C))
A7: MA.8.NSO.1.2 | B7: 8 | C7: Plot, order and compare rational and irrational numbers, represented in various forms. | D7: Boundary: not the expectation to work with the number e. Boundary: the expectation is to plot, order and compare square roots and cube roots. Clarification: the expectation is to use symbols (<, > or =). | E7: 2 | F7: Unit 2 (before 23 Sep) | I7: PM2-R1 (14 Dec) | J7: =IF(SUMIF('Unit tests'!$E:$E,A7,'Unit tests'!$C:$C)=0,"",SUMIF('Unit tests'!$E:$E,A7,'Unit tests'!$C:$C))
A8: MA.7.NSO.1.1 | B8: 7 | C8: Know and apply the Laws of Exponents to evaluate numerical expressions and generate equivalent numerical expressions, limited to whole-number exponents and rational number bases. | D8: Boundary: aⁿ ÷ aᵐ = aᵖ must result in a whole-number p. → superseded within the course by MA.8.NSO.1.3. | E8: 3 | F8: 3.01 (Wed 23 Sep); 3.02 (Thu 24 Sep); 3.03 (Fri 25 Sep) | G8: 46288 | H8: 46290 | J8: =IF(SUMIF('Unit tests'!$E:$E,A8,'Unit tests'!$C:$C)=0,"",SUMIF('Unit tests'!$E:$E,A8,'Unit tests'!$C:$C)) -> 9 | K8: SZQ, 5SK, 8DA, BFA, WFW, XNC, KBE, ZE9
A9: MA.8.NSO.1.3 | B9: 8 | C9: Extend previous understanding of the Laws of Exponents to include integer exponents. Apply the Laws of Exponents to evaluate numerical expressions and generate equivalent numerical expressions, limited to integer exponents and rational number bases, with procedural fluency. | D9: Clarification: refer to the K-12 Formulas (Appendix E) for the Laws of Exponents. Boundary (B1G-M): includes negative integer exponents; does not include fractional exponents. Vertical: Gr 7 was whole-number exponents with whole-number results → Gr 8 adds integer exponents. | E9: 3 | F9: 3.01 (Wed 23 Sep); 3.02 (Thu 24 Sep); 3.03 (Fri 25 Sep); 3.04 (Mon 28 Sep); 3.05 (Tue 29 Sep); 3.06+07 (Wed 30 Sep) | G9: 46288 | H9: 46295 | I9: PM2-R1 (14 Dec) | J9: =IF(SUMIF('Unit tests'!$E:$E,A9,'Unit tests'!$C:$C)=0,"",SUMIF('Unit tests'!$E:$E,A9,'Unit tests'!$C:$C)) -> 9 | K9: SZQ, 5SK, 8DA, BFA, WFW, XNC, KBE, ZE9, YBB, WGS, VLM, 6T7, QDM
A10: MA.8.AR.1.1 | B10: 8 | C10: Apply the Laws of Exponents to generate equivalent algebraic expressions, limited to integer exponents and monomial bases. | D10: Clarification: refer to the K-12 Formulas (Appendix E). B1G-M definition to use: "a base may be a product of a coefficient and one or more variables with integer exponents." | E10: 3, 14 | F10: T-A1 (Mon 5 Oct); T-A2 (Tue 6 Oct); 14.01–04 (Wed 31 Mar) | G10: 46300 | H10: 46477 | I10: PM2-R3 (16 Dec) | J10: =IF(SUMIF('Unit tests'!$E:$E,A10,'Unit tests'!$C:$C)=0,"",SUMIF('Unit tests'!$E:$E,A10,'Unit tests'!$C:$C)) -> 8 | K10: TR9, 2CU, C8L, 2NL, 85P
A11: MA.8.NSO.1.4 | B11: 8 | C11: Express numbers in scientific notation to represent and approximate very large or very small quantities. Determine how many times larger or smaller one number is compared to a second number. | E11: 3 | F11: 3.08 (Wed 7 Oct); 3.09 (Fri 9 Oct) | G11: 46302 | H11: 46304 | I11: PM2-R1 (14 Dec) | J11: =IF(SUMIF('Unit tests'!$E:$E,A11,'Unit tests'!$C:$C)=0,"",SUMIF('Unit tests'!$E:$E,A11,'Unit tests'!$C:$C)) -> 10 | K11: 2AL, WEZ, LJQ, 85M, KDR, SKD
A12: MA.8.NSO.1.5 | B12: 8 | C12: Add, subtract, multiply and divide numbers expressed in scientific notation with procedural fluency. | D12: Boundary: for addition and subtraction, exponents are limited to within 2 of each other. | E12: 4 | F12: 4.01 (Fri 16 Oct); 4.02+03 (Mon 19 Oct) | G12: 46311 | H12: 46314 | I12: PM2-R1 (14 Dec) | J12: =IF(SUMIF('Unit tests'!$E:$E,A12,'Unit tests'!$C:$C)=0,"",SUMIF('Unit tests'!$E:$E,A12,'Unit tests'!$C:$C)) -> 12 | K12: HUR, YZU, SGT
A13: MA.8.NSO.1.6 | B13: 8 | C13: Solve real-world problems involving operations with numbers expressed in scientific notation. | D13: Clarification: includes recognizing the importance of significant digits when physical measurements are involved. Boundary: same within-2 exponent limit on addition and subtraction. | E13: 4 | F13: 4.04 (Tue 20 Oct) | G13: 46315 | H13: 46315 | I13: PM2-R1 (14 Dec) | J13: =IF(SUMIF('Unit tests'!$E:$E,A13,'Unit tests'!$C:$C)=0,"",SUMIF('Unit tests'!$E:$E,A13,'Unit tests'!$C:$C)) -> 9 | K13: D5S
A14: MA.8.NSO.1.7 | B14: 8 | C14: Solve multi-step mathematical and real-world problems involving the order of operations with rational numbers including exponents and radicals. | D14: Boundary: 6 or fewer steps. Boundary: simplify radicals by factoring square roots of perfect squares up to 225 and cube roots of perfect cubes from −125 to 125. | E14: 4 | F14: 4.05 (Wed 21 Oct); 4.06 (Thu 22 Oct); 4.07+08 (Fri 23 Oct) | G14: 46316 | H14: 46318 | I14: PM2-R1 (14 Dec) | J14: =IF(SUMIF('Unit tests'!$E:$E,A14,'Unit tests'!$C:$C)=0,"",SUMIF('Unit tests'!$E:$E,A14,'Unit tests'!$C:$C)) -> 13 | K14: D8J, DPG
A15: MA.7.GR.1.5 | B15: 7 | C15: Solve mathematical and real-world problems involving dimensions and areas of geometric figures, including scale drawings and scale factors. | D15: Clarification: if the scale factor is k, area scales by k². → this is the direct feeder to MA.8.GR.2.2 (dilation scale factor). | E15: 5 | F15: 5.01 (Wed 28 Oct); 5.02+03 (Thu 29 Oct); 5.04 (Fri 30 Oct) | G15: 46323 | H15: 46325 | J15: =IF(SUMIF('Unit tests'!$E:$E,A15,'Unit tests'!$C:$C)=0,"",SUMIF('Unit tests'!$E:$E,A15,'Unit tests'!$C:$C)) | K15: WEA, ZC6, XHM, 84H, KCM
A16: MA.7.AR.3.3 | B16: 7 | C16: Solve mathematical and real-world problems involving the conversion of units across different measurement systems. | D16: Boundary: length, area, weight, mass, volume, money. Conversion ratios are on the reference sheet. | E16: 5 | F16: 5.06+07 (Mon 2 Nov); 5.08+09 (Tue 3 Nov); 5.10+11 (Wed 4 Nov) | G16: 46328 | H16: 46330 | J16: =IF(SUMIF('Unit tests'!$E:$E,A16,'Unit tests'!$C:$C)=0,"",SUMIF('Unit tests'!$E:$E,A16,'Unit tests'!$C:$C)) | K16: E8Z, 4B8, HW2, VVS, UCT
A17: MA.7.AR.4.5 | B17: 7 | C17: Solve real-world problems involving proportional relationships. | E17: 5, 7 | F17: 5.10+11 (Wed 4 Nov); 7.07 (Wed 9 Dec) | G17: 46330 | H17: 46365 | J17: =IF(SUMIF('Unit tests'!$E:$E,A17,'Unit tests'!$C:$C)=0,"",SUMIF('Unit tests'!$E:$E,A17,'Unit tests'!$C:$C)) | K17: VVS, UCT, 5A9
A18: MA.8.GR.1.3 | B18: 8 | C18: Use the Triangle Inequality Theorem to determine if a triangle can be formed from a given set of sides. Use the converse of the Pythagorean Theorem to determine if a right triangle can be formed from a given set of sides. | E18: 6 | F18: 6.01+02 (Mon 9 Nov) | G18: 46335 | H18: 46335 | I18: PM2-R2 (15 Dec) | J18: =IF(SUMIF('Unit tests'!$E:$E,A18,'Unit tests'!$C:$C)=0,"",SUMIF('Unit tests'!$E:$E,A18,'Unit tests'!$C:$C)) | K18: 2N5, EQZ
A19: MA.8.GR.1.1 | B19: 8 | C19: Apply the Pythagorean Theorem to solve mathematical and real-world problems involving unknown side lengths in right triangles. | D19: Clarification: explore right triangles with natural-number side lengths to illustrate the theorem. ⚠ The expectation is to MEMORIZE the Pythagorean Theorem. It is not on the reference sheet. Boundary: radicands limited to whole numbers up to 225. | E19: 6 | F19: 6.03 (Tue 10 Nov); 6.04 (Thu 12 Nov) | G19: 46336 | H19: 46338 | I19: PM2-R2 (15 Dec) | J19: =IF(SUMIF('Unit tests'!$E:$E,A19,'Unit tests'!$C:$C)=0,"",SUMIF('Unit tests'!$E:$E,A19,'Unit tests'!$C:$C)) | K19: MTM, 87U
